2019-10-01 09:41:55,213 [INFO]   * Running on http://0.0.0.0:5000/ (Press CTRL+C to quit)
2019-10-01 09:42:52,565 [INFO]  127.0.0.1 - - [01/Oct/2019 09:42:52] "POST /predict HTTP/1.1" 200 -
2019-10-01 09:46:14,302 [INFO]  127.0.0.1 - - [01/Oct/2019 09:46:14] "POST /predict HTTP/1.1" 200 -
2019-10-01 09:46:38,116 [INFO]   * Running on http://0.0.0.0:5000/ (Press CTRL+C to quit)
2019-10-01 09:46:42,007 [INFO]  127.0.0.1 - - [01/Oct/2019 09:46:42] "POST /predict HTTP/1.1" 200 -
2019-10-01 09:47:22,386 [INFO]   * Running on http://0.0.0.0:5000/ (Press CTRL+C to quit)
2019-10-01 09:47:33,110 [INFO]  Here
2019-10-01 09:47:33,115 [INFO]  127.0.0.1 - - [01/Oct/2019 09:47:33] "POST /predict HTTP/1.1" 200 -
2019-10-01 09:48:38,043 [INFO]   * Running on http://0.0.0.0:5000/ (Press CTRL+C to quit)
2019-10-01 09:49:02,537 [INFO]  127.0.0.1 - - [01/Oct/2019 09:49:02] "POST /predict HTTP/1.1" 200 -
2019-10-01 09:49:59,943 [INFO]  Have files
2019-10-01 09:49:59,963 [INFO]  (64, 64)
2019-10-01 09:49:59,965 [INFO]  127.0.0.1 - - [01/Oct/2019 09:49:59] "POST /predict HTTP/1.1" 200 -
2019-10-01 14:49:41,561 [INFO]   * Running on http://0.0.0.0:5000/ (Press CTRL+C to quit)
2019-10-01 15:03:10,247 [WARNI]  file_cache is unavailable when using oauth2client >= 4.0.0 or google-auth
Traceback (most recent call last):
  File "C:\Users\zachary.mostowsky\AppData\Local\Continuum\anaconda3\envs\gcp-demo1\lib\site-packages\googleapiclient\discovery_cache\__init__.py", line 36, in autodetect
    from google.appengine.api import memcache
ModuleNotFoundError: No module named 'google.appengine'

During handling of the above exception, another exception occurred:

Traceback (most recent call last):
  File "C:\Users\zachary.mostowsky\AppData\Local\Continuum\anaconda3\envs\gcp-demo1\lib\site-packages\googleapiclient\discovery_cache\file_cache.py", line 33, in <module>
    from oauth2client.contrib.locked_file import LockedFile
ModuleNotFoundError: No module named 'oauth2client'

During handling of the above exception, another exception occurred:

Traceback (most recent call last):
  File "C:\Users\zachary.mostowsky\AppData\Local\Continuum\anaconda3\envs\gcp-demo1\lib\site-packages\googleapiclient\discovery_cache\file_cache.py", line 37, in <module>
    from oauth2client.locked_file import LockedFile
ModuleNotFoundError: No module named 'oauth2client'

During handling of the above exception, another exception occurred:

Traceback (most recent call last):
  File "C:\Users\zachary.mostowsky\AppData\Local\Continuum\anaconda3\envs\gcp-demo1\lib\site-packages\googleapiclient\discovery_cache\__init__.py", line 41, in autodetect
    from . import file_cache
  File "C:\Users\zachary.mostowsky\AppData\Local\Continuum\anaconda3\envs\gcp-demo1\lib\site-packages\googleapiclient\discovery_cache\file_cache.py", line 41, in <module>
    'file_cache is unavailable when using oauth2client >= 4.0.0 or google-auth')
ImportError: file_cache is unavailable when using oauth2client >= 4.0.0 or google-auth
2019-10-01 15:03:10,249 [INFO]  URL being requested: GET https://www.googleapis.com/discovery/v1/apis/ml/v1/rest
2019-10-01 15:03:13,645 [INFO]  Compute Engine Metadata server unavailable onattempt 1 of 3
2019-10-01 15:03:16,646 [INFO]  Compute Engine Metadata server unavailable onattempt 2 of 3
2019-10-01 15:03:19,648 [INFO]  Compute Engine Metadata server unavailable onattempt 3 of 3
2019-10-01 15:07:08,172 [WARNI]  file_cache is unavailable when using oauth2client >= 4.0.0 or google-auth
Traceback (most recent call last):
  File "C:\Users\zachary.mostowsky\AppData\Local\Continuum\anaconda3\envs\gcp-demo1\lib\site-packages\googleapiclient\discovery_cache\__init__.py", line 36, in autodetect
    from google.appengine.api import memcache
ModuleNotFoundError: No module named 'google.appengine'

During handling of the above exception, another exception occurred:

Traceback (most recent call last):
  File "C:\Users\zachary.mostowsky\AppData\Local\Continuum\anaconda3\envs\gcp-demo1\lib\site-packages\googleapiclient\discovery_cache\file_cache.py", line 33, in <module>
    from oauth2client.contrib.locked_file import LockedFile
ModuleNotFoundError: No module named 'oauth2client'

During handling of the above exception, another exception occurred:

Traceback (most recent call last):
  File "C:\Users\zachary.mostowsky\AppData\Local\Continuum\anaconda3\envs\gcp-demo1\lib\site-packages\googleapiclient\discovery_cache\file_cache.py", line 37, in <module>
    from oauth2client.locked_file import LockedFile
ModuleNotFoundError: No module named 'oauth2client'

During handling of the above exception, another exception occurred:

Traceback (most recent call last):
  File "C:\Users\zachary.mostowsky\AppData\Local\Continuum\anaconda3\envs\gcp-demo1\lib\site-packages\googleapiclient\discovery_cache\__init__.py", line 41, in autodetect
    from . import file_cache
  File "C:\Users\zachary.mostowsky\AppData\Local\Continuum\anaconda3\envs\gcp-demo1\lib\site-packages\googleapiclient\discovery_cache\file_cache.py", line 41, in <module>
    'file_cache is unavailable when using oauth2client >= 4.0.0 or google-auth')
ImportError: file_cache is unavailable when using oauth2client >= 4.0.0 or google-auth
2019-10-01 15:07:08,173 [INFO]  URL being requested: GET https://www.googleapis.com/discovery/v1/apis/ml/v1/rest
2019-10-01 15:12:11,292 [WARNI]  file_cache is unavailable when using oauth2client >= 4.0.0 or google-auth
Traceback (most recent call last):
  File "C:\Users\zachary.mostowsky\AppData\Local\Continuum\anaconda3\envs\gcp-demo1\lib\site-packages\googleapiclient\discovery_cache\__init__.py", line 36, in autodetect
    from google.appengine.api import memcache
ModuleNotFoundError: No module named 'google.appengine'

During handling of the above exception, another exception occurred:

Traceback (most recent call last):
  File "C:\Users\zachary.mostowsky\AppData\Local\Continuum\anaconda3\envs\gcp-demo1\lib\site-packages\googleapiclient\discovery_cache\file_cache.py", line 33, in <module>
    from oauth2client.contrib.locked_file import LockedFile
ModuleNotFoundError: No module named 'oauth2client.contrib.locked_file'

During handling of the above exception, another exception occurred:

Traceback (most recent call last):
  File "C:\Users\zachary.mostowsky\AppData\Local\Continuum\anaconda3\envs\gcp-demo1\lib\site-packages\googleapiclient\discovery_cache\file_cache.py", line 37, in <module>
    from oauth2client.locked_file import LockedFile
ModuleNotFoundError: No module named 'oauth2client.locked_file'

During handling of the above exception, another exception occurred:

Traceback (most recent call last):
  File "C:\Users\zachary.mostowsky\AppData\Local\Continuum\anaconda3\envs\gcp-demo1\lib\site-packages\googleapiclient\discovery_cache\__init__.py", line 41, in autodetect
    from . import file_cache
  File "C:\Users\zachary.mostowsky\AppData\Local\Continuum\anaconda3\envs\gcp-demo1\lib\site-packages\googleapiclient\discovery_cache\file_cache.py", line 41, in <module>
    'file_cache is unavailable when using oauth2client >= 4.0.0 or google-auth')
ImportError: file_cache is unavailable when using oauth2client >= 4.0.0 or google-auth
2019-10-01 15:12:11,293 [INFO]  URL being requested: GET https://www.googleapis.com/discovery/v1/apis/ml/v1/rest
2019-10-01 15:16:08,546 [WARNI]  file_cache is unavailable when using oauth2client >= 4.0.0 or google-auth
Traceback (most recent call last):
  File "C:\Users\zachary.mostowsky\AppData\Local\Continuum\anaconda3\envs\gcp-demo1\lib\site-packages\googleapiclient\discovery_cache\__init__.py", line 36, in autodetect
    from google.appengine.api import memcache
ModuleNotFoundError: No module named 'google.appengine'

During handling of the above exception, another exception occurred:

Traceback (most recent call last):
  File "C:\Users\zachary.mostowsky\AppData\Local\Continuum\anaconda3\envs\gcp-demo1\lib\site-packages\googleapiclient\discovery_cache\file_cache.py", line 33, in <module>
    from oauth2client.contrib.locked_file import LockedFile
ModuleNotFoundError: No module named 'oauth2client.contrib.locked_file'

During handling of the above exception, another exception occurred:

Traceback (most recent call last):
  File "C:\Users\zachary.mostowsky\AppData\Local\Continuum\anaconda3\envs\gcp-demo1\lib\site-packages\googleapiclient\discovery_cache\file_cache.py", line 37, in <module>
    from oauth2client.locked_file import LockedFile
ModuleNotFoundError: No module named 'oauth2client.locked_file'

During handling of the above exception, another exception occurred:

Traceback (most recent call last):
  File "C:\Users\zachary.mostowsky\AppData\Local\Continuum\anaconda3\envs\gcp-demo1\lib\site-packages\googleapiclient\discovery_cache\__init__.py", line 41, in autodetect
    from . import file_cache
  File "C:\Users\zachary.mostowsky\AppData\Local\Continuum\anaconda3\envs\gcp-demo1\lib\site-packages\googleapiclient\discovery_cache\file_cache.py", line 41, in <module>
    'file_cache is unavailable when using oauth2client >= 4.0.0 or google-auth')
ImportError: file_cache is unavailable when using oauth2client >= 4.0.0 or google-auth
2019-10-01 15:16:08,548 [INFO]  URL being requested: GET https://www.googleapis.com/discovery/v1/apis/ml/v1/rest
2019-10-01 15:19:50,557 [WARNI]  file_cache is unavailable when using oauth2client >= 4.0.0 or google-auth
Traceback (most recent call last):
  File "C:\Users\zachary.mostowsky\AppData\Local\Continuum\anaconda3\envs\gcp-demo1\lib\site-packages\googleapiclient\discovery_cache\__init__.py", line 36, in autodetect
    from google.appengine.api import memcache
ModuleNotFoundError: No module named 'google.appengine'

During handling of the above exception, another exception occurred:

Traceback (most recent call last):
  File "C:\Users\zachary.mostowsky\AppData\Local\Continuum\anaconda3\envs\gcp-demo1\lib\site-packages\googleapiclient\discovery_cache\file_cache.py", line 33, in <module>
    from oauth2client.contrib.locked_file import LockedFile
ModuleNotFoundError: No module named 'oauth2client.contrib.locked_file'

During handling of the above exception, another exception occurred:

Traceback (most recent call last):
  File "C:\Users\zachary.mostowsky\AppData\Local\Continuum\anaconda3\envs\gcp-demo1\lib\site-packages\googleapiclient\discovery_cache\file_cache.py", line 37, in <module>
    from oauth2client.locked_file import LockedFile
ModuleNotFoundError: No module named 'oauth2client.locked_file'

During handling of the above exception, another exception occurred:

Traceback (most recent call last):
  File "C:\Users\zachary.mostowsky\AppData\Local\Continuum\anaconda3\envs\gcp-demo1\lib\site-packages\googleapiclient\discovery_cache\__init__.py", line 41, in autodetect
    from . import file_cache
  File "C:\Users\zachary.mostowsky\AppData\Local\Continuum\anaconda3\envs\gcp-demo1\lib\site-packages\googleapiclient\discovery_cache\file_cache.py", line 41, in <module>
    'file_cache is unavailable when using oauth2client >= 4.0.0 or google-auth')
ImportError: file_cache is unavailable when using oauth2client >= 4.0.0 or google-auth
2019-10-01 15:19:50,559 [INFO]  URL being requested: GET https://www.googleapis.com/discovery/v1/apis/ml/v1/rest
2019-10-01 15:20:04,467 [WARNI]  file_cache is unavailable when using oauth2client >= 4.0.0 or google-auth
Traceback (most recent call last):
  File "C:\Users\zachary.mostowsky\AppData\Local\Continuum\anaconda3\envs\gcp-demo1\lib\site-packages\googleapiclient\discovery_cache\__init__.py", line 36, in autodetect
    from google.appengine.api import memcache
ModuleNotFoundError: No module named 'google.appengine'

During handling of the above exception, another exception occurred:

Traceback (most recent call last):
  File "C:\Users\zachary.mostowsky\AppData\Local\Continuum\anaconda3\envs\gcp-demo1\lib\site-packages\googleapiclient\discovery_cache\file_cache.py", line 33, in <module>
    from oauth2client.contrib.locked_file import LockedFile
ModuleNotFoundError: No module named 'oauth2client.contrib.locked_file'

During handling of the above exception, another exception occurred:

Traceback (most recent call last):
  File "C:\Users\zachary.mostowsky\AppData\Local\Continuum\anaconda3\envs\gcp-demo1\lib\site-packages\googleapiclient\discovery_cache\file_cache.py", line 37, in <module>
    from oauth2client.locked_file import LockedFile
ModuleNotFoundError: No module named 'oauth2client.locked_file'

During handling of the above exception, another exception occurred:

Traceback (most recent call last):
  File "C:\Users\zachary.mostowsky\AppData\Local\Continuum\anaconda3\envs\gcp-demo1\lib\site-packages\googleapiclient\discovery_cache\__init__.py", line 41, in autodetect
    from . import file_cache
  File "C:\Users\zachary.mostowsky\AppData\Local\Continuum\anaconda3\envs\gcp-demo1\lib\site-packages\googleapiclient\discovery_cache\file_cache.py", line 41, in <module>
    'file_cache is unavailable when using oauth2client >= 4.0.0 or google-auth')
ImportError: file_cache is unavailable when using oauth2client >= 4.0.0 or google-auth
2019-10-01 15:20:04,468 [INFO]  URL being requested: GET https://www.googleapis.com/discovery/v1/apis/ml/v1/rest
2019-10-01 15:21:58,809 [WARNI]  file_cache is unavailable when using oauth2client >= 4.0.0 or google-auth
Traceback (most recent call last):
  File "C:\Users\zachary.mostowsky\AppData\Local\Continuum\anaconda3\envs\gcp-demo1\lib\site-packages\googleapiclient\discovery_cache\__init__.py", line 36, in autodetect
    from google.appengine.api import memcache
ModuleNotFoundError: No module named 'google.appengine'

During handling of the above exception, another exception occurred:

Traceback (most recent call last):
  File "C:\Users\zachary.mostowsky\AppData\Local\Continuum\anaconda3\envs\gcp-demo1\lib\site-packages\googleapiclient\discovery_cache\file_cache.py", line 33, in <module>
    from oauth2client.contrib.locked_file import LockedFile
ModuleNotFoundError: No module named 'oauth2client.contrib.locked_file'

During handling of the above exception, another exception occurred:

Traceback (most recent call last):
  File "C:\Users\zachary.mostowsky\AppData\Local\Continuum\anaconda3\envs\gcp-demo1\lib\site-packages\googleapiclient\discovery_cache\file_cache.py", line 37, in <module>
    from oauth2client.locked_file import LockedFile
ModuleNotFoundError: No module named 'oauth2client.locked_file'

During handling of the above exception, another exception occurred:

Traceback (most recent call last):
  File "C:\Users\zachary.mostowsky\AppData\Local\Continuum\anaconda3\envs\gcp-demo1\lib\site-packages\googleapiclient\discovery_cache\__init__.py", line 41, in autodetect
    from . import file_cache
  File "C:\Users\zachary.mostowsky\AppData\Local\Continuum\anaconda3\envs\gcp-demo1\lib\site-packages\googleapiclient\discovery_cache\file_cache.py", line 41, in <module>
    'file_cache is unavailable when using oauth2client >= 4.0.0 or google-auth')
ImportError: file_cache is unavailable when using oauth2client >= 4.0.0 or google-auth
2019-10-01 15:21:58,811 [INFO]  URL being requested: GET https://www.googleapis.com/discovery/v1/apis/ml/v1/rest
2019-10-01 15:21:59,061 [INFO]  URL being requested: POST https://ml.googleapis.com/v1/projects/ml-sandbox-1-191918/models/Cash_Or_Credit:predict?alt=json
2019-10-01 15:21:59,810 [WARNI]  Invalid JSON content from response: b'{\n  "error": {\n    "code": 403,\n    "message": "Access to model denied.",\n    "status": "PERMISSION_DENIED"\n  }\n}\n'
2019-10-01 15:23:30,827 [INFO]  URL being requested: GET https://www.googleapis.com/discovery/v1/apis/ml/v1/rest
2019-10-01 15:23:31,158 [INFO]  URL being requested: POST https://ml.googleapis.com/v1/projects/ml-sandbox-1-191918/models/Cash_Or_Credit:predict?alt=json
2019-10-01 15:23:31,805 [WARNI]  Invalid JSON content from response: b'{\n  "error": {\n    "code": 403,\n    "message": "Access to model denied.",\n    "status": "PERMISSION_DENIED"\n  }\n}\n'
2019-10-01 15:26:21,032 [INFO]  URL being requested: GET https://www.googleapis.com/discovery/v1/apis/ml/v1/rest
2019-10-01 15:26:21,362 [INFO]  URL being requested: POST https://ml.googleapis.com/v1/projects/ml-sandbox-1-191918/models/Cash_Or_Credit:predict?alt=json
2019-10-01 15:26:22,010 [WARNI]  Invalid JSON content from response: b'{\n  "error": {\n    "code": 403,\n    "message": "Access to model denied.",\n    "status": "PERMISSION_DENIED"\n  }\n}\n'
2019-10-01 15:27:05,049 [INFO]  URL being requested: GET https://www.googleapis.com/discovery/v1/apis/ml/v1/rest
2019-10-01 15:27:05,386 [INFO]  URL being requested: POST https://ml.googleapis.com/v1/projects/ml-sandbox-1/models/Cash_Or_Credit:predict?alt=json
2019-10-01 15:27:05,606 [WARNI]  Invalid JSON content from response: b'{\n  "error": {\n    "code": 403,\n    "message": "Cloud Machine Learning Engine has not been used in project 365008291484 before or it is disabled. Enable it by visiting https://console.developers.google.com/apis/api/ml.googleapis.com/overview?project=365008291484 then retry. If you enabled this API recently, wait a few minutes for the action to propagate to our systems and retry.",\n    "status": "PERMISSION_DENIED",\n    "details": [\n      {\n        "@type": "type.googleapis.com/google.rpc.Help",\n        "links": [\n          {\n            "description": "Google developers console API activation",\n            "url": "https://console.developers.google.com/apis/api/ml.googleapis.com/overview?project=365008291484"\n          }\n        ]\n      }\n    ]\n  }\n}\n'
2019-10-01 15:27:29,951 [INFO]  URL being requested: GET https://www.googleapis.com/discovery/v1/apis/ml/v1/rest
2019-10-01 15:27:30,277 [INFO]  URL being requested: POST https://ml.googleapis.com/v1/projects/ml-sandbox-1/models/Cash_Or_Credit:predict?alt=json
2019-10-01 15:27:30,490 [WARNI]  Invalid JSON content from response: b'{\n  "error": {\n    "code": 403,\n    "message": "Cloud Machine Learning Engine has not been used in project 365008291484 before or it is disabled. Enable it by visiting https://console.developers.google.com/apis/api/ml.googleapis.com/overview?project=365008291484 then retry. If you enabled this API recently, wait a few minutes for the action to propagate to our systems and retry.",\n    "status": "PERMISSION_DENIED",\n    "details": [\n      {\n        "@type": "type.googleapis.com/google.rpc.Help",\n        "links": [\n          {\n            "description": "Google developers console API activation",\n            "url": "https://console.developers.google.com/apis/api/ml.googleapis.com/overview?project=365008291484"\n          }\n        ]\n      }\n    ]\n  }\n}\n'
2019-10-01 15:29:35,388 [INFO]  URL being requested: GET https://www.googleapis.com/discovery/v1/apis/ml/v1/rest
2019-10-01 15:29:35,710 [INFO]  URL being requested: POST https://ml.googleapis.com/v1/projects/ml-sandbox-1/models/Cash_Or_Credit:predict?alt=json
2019-10-01 15:29:35,924 [WARNI]  Invalid JSON content from response: b'{\n  "error": {\n    "code": 403,\n    "message": "Cloud Machine Learning Engine has not been used in project 365008291484 before or it is disabled. Enable it by visiting https://console.developers.google.com/apis/api/ml.googleapis.com/overview?project=365008291484 then retry. If you enabled this API recently, wait a few minutes for the action to propagate to our systems and retry.",\n    "status": "PERMISSION_DENIED",\n    "details": [\n      {\n        "@type": "type.googleapis.com/google.rpc.Help",\n        "links": [\n          {\n            "description": "Google developers console API activation",\n            "url": "https://console.developers.google.com/apis/api/ml.googleapis.com/overview?project=365008291484"\n          }\n        ]\n      }\n    ]\n  }\n}\n'
2019-10-01 15:30:42,438 [INFO]  URL being requested: GET https://www.googleapis.com/discovery/v1/apis/ml/v1/rest
2019-10-01 15:30:42,788 [INFO]  URL being requested: POST https://ml.googleapis.com/v1/projects/ml-sandbox-1/models/Cash_Or_Credit:predict?alt=json
2019-10-01 15:30:43,010 [WARNI]  Invalid JSON content from response: b'{\n  "error": {\n    "code": 403,\n    "message": "Cloud Machine Learning Engine has not been used in project 365008291484 before or it is disabled. Enable it by visiting https://console.developers.google.com/apis/api/ml.googleapis.com/overview?project=365008291484 then retry. If you enabled this API recently, wait a few minutes for the action to propagate to our systems and retry.",\n    "status": "PERMISSION_DENIED",\n    "details": [\n      {\n        "@type": "type.googleapis.com/google.rpc.Help",\n        "links": [\n          {\n            "description": "Google developers console API activation",\n            "url": "https://console.developers.google.com/apis/api/ml.googleapis.com/overview?project=365008291484"\n          }\n        ]\n      }\n    ]\n  }\n}\n'
2019-10-01 15:32:04,074 [INFO]  URL being requested: GET https://www.googleapis.com/discovery/v1/apis/ml/v1/rest
2019-10-01 15:32:04,449 [INFO]  URL being requested: POST https://ml.googleapis.com/v1/projects/ml-sandbox-1/models/Cash_Or_Credit:predict?alt=json
2019-10-01 15:32:04,683 [WARNI]  Invalid JSON content from response: b'{\n  "error": {\n    "code": 403,\n    "message": "Cloud Machine Learning Engine has not been used in project 365008291484 before or it is disabled. Enable it by visiting https://console.developers.google.com/apis/api/ml.googleapis.com/overview?project=365008291484 then retry. If you enabled this API recently, wait a few minutes for the action to propagate to our systems and retry.",\n    "status": "PERMISSION_DENIED",\n    "details": [\n      {\n        "@type": "type.googleapis.com/google.rpc.Help",\n        "links": [\n          {\n            "description": "Google developers console API activation",\n            "url": "https://console.developers.google.com/apis/api/ml.googleapis.com/overview?project=365008291484"\n          }\n        ]\n      }\n    ]\n  }\n}\n'
2019-10-01 15:33:24,567 [INFO]  URL being requested: GET https://www.googleapis.com/discovery/v1/apis/ml/v1/rest
2019-10-01 15:33:24,907 [INFO]  URL being requested: POST https://ml.googleapis.com/v1/projects/ml-sandbox-1/models/Cash_Or_Credit:predict?alt=json
2019-10-01 15:33:25,127 [WARNI]  Invalid JSON content from response: b'{\n  "error": {\n    "code": 403,\n    "message": "Cloud Machine Learning Engine has not been used in project 365008291484 before or it is disabled. Enable it by visiting https://console.developers.google.com/apis/api/ml.googleapis.com/overview?project=365008291484 then retry. If you enabled this API recently, wait a few minutes for the action to propagate to our systems and retry.",\n    "status": "PERMISSION_DENIED",\n    "details": [\n      {\n        "@type": "type.googleapis.com/google.rpc.Help",\n        "links": [\n          {\n            "description": "Google developers console API activation",\n            "url": "https://console.developers.google.com/apis/api/ml.googleapis.com/overview?project=365008291484"\n          }\n        ]\n      }\n    ]\n  }\n}\n'
2019-10-01 15:35:26,988 [INFO]  URL being requested: GET https://www.googleapis.com/discovery/v1/apis/ml/v1/rest
2019-10-01 15:35:27,318 [INFO]  URL being requested: POST https://ml.googleapis.com/v1/projects/ml-sandbox-1/models/Cash_Or_Credit:predict?alt=json
2019-10-01 15:35:27,534 [WARNI]  Invalid JSON content from response: b'{\n  "error": {\n    "code": 403,\n    "message": "Cloud Machine Learning Engine has not been used in project 365008291484 before or it is disabled. Enable it by visiting https://console.developers.google.com/apis/api/ml.googleapis.com/overview?project=365008291484 then retry. If you enabled this API recently, wait a few minutes for the action to propagate to our systems and retry.",\n    "status": "PERMISSION_DENIED",\n    "details": [\n      {\n        "@type": "type.googleapis.com/google.rpc.Help",\n        "links": [\n          {\n            "description": "Google developers console API activation",\n            "url": "https://console.developers.google.com/apis/api/ml.googleapis.com/overview?project=365008291484"\n          }\n        ]\n      }\n    ]\n  }\n}\n'
2019-10-01 15:39:56,963 [INFO]  URL being requested: GET https://www.googleapis.com/discovery/v1/apis/ml/v1/rest
2019-10-01 15:39:57,321 [INFO]  URL being requested: POST https://ml.googleapis.com/v1/projects/ml-sandbox-1/models/Cash_Or_Credit:predict?alt=json
2019-10-01 15:39:57,570 [WARNI]  Invalid JSON content from response: b'{\n  "error": {\n    "code": 403,\n    "message": "Cloud Machine Learning Engine has not been used in project 365008291484 before or it is disabled. Enable it by visiting https://console.developers.google.com/apis/api/ml.googleapis.com/overview?project=365008291484 then retry. If you enabled this API recently, wait a few minutes for the action to propagate to our systems and retry.",\n    "status": "PERMISSION_DENIED",\n    "details": [\n      {\n        "@type": "type.googleapis.com/google.rpc.Help",\n        "links": [\n          {\n            "description": "Google developers console API activation",\n            "url": "https://console.developers.google.com/apis/api/ml.googleapis.com/overview?project=365008291484"\n          }\n        ]\n      }\n    ]\n  }\n}\n'
2019-10-01 15:40:45,280 [INFO]  URL being requested: GET https://www.googleapis.com/discovery/v1/apis/ml/v1/rest
2019-10-01 15:40:45,612 [INFO]  URL being requested: POST https://ml.googleapis.com/v1/projects/ml-sandbox-1/models/Cash_Or_Credit:predict?alt=json
2019-10-01 15:40:45,818 [WARNI]  Invalid JSON content from response: b'{\n  "error": {\n    "code": 403,\n    "message": "Cloud Machine Learning Engine has not been used in project 365008291484 before or it is disabled. Enable it by visiting https://console.developers.google.com/apis/api/ml.googleapis.com/overview?project=365008291484 then retry. If you enabled this API recently, wait a few minutes for the action to propagate to our systems and retry.",\n    "status": "PERMISSION_DENIED",\n    "details": [\n      {\n        "@type": "type.googleapis.com/google.rpc.Help",\n        "links": [\n          {\n            "description": "Google developers console API activation",\n            "url": "https://console.developers.google.com/apis/api/ml.googleapis.com/overview?project=365008291484"\n          }\n        ]\n      }\n    ]\n  }\n}\n'
2019-10-01 15:41:46,099 [INFO]  URL being requested: GET https://www.googleapis.com/discovery/v1/apis/ml/v1/rest
2019-10-01 15:41:46,444 [INFO]  URL being requested: POST https://ml.googleapis.com/v1/projects/ml-sandbox-1/models/Cash_Or_Credit:predict?alt=json
2019-10-01 15:41:46,650 [WARNI]  Invalid JSON content from response: b'{\n  "error": {\n    "code": 403,\n    "message": "Cloud Machine Learning Engine has not been used in project 365008291484 before or it is disabled. Enable it by visiting https://console.developers.google.com/apis/api/ml.googleapis.com/overview?project=365008291484 then retry. If you enabled this API recently, wait a few minutes for the action to propagate to our systems and retry.",\n    "status": "PERMISSION_DENIED",\n    "details": [\n      {\n        "@type": "type.googleapis.com/google.rpc.Help",\n        "links": [\n          {\n            "description": "Google developers console API activation",\n            "url": "https://console.developers.google.com/apis/api/ml.googleapis.com/overview?project=365008291484"\n          }\n        ]\n      }\n    ]\n  }\n}\n'
2019-10-01 15:48:58,881 [INFO]  URL being requested: GET https://www.googleapis.com/discovery/v1/apis/ml/v1/rest
2019-10-01 15:48:59,214 [INFO]  URL being requested: POST https://ml.googleapis.com/v1/projects/ml-sandbox-1/models/Cash_Or_Credit:predict?alt=json
2019-10-01 15:48:59,442 [WARNI]  Invalid JSON content from response: b'{\n  "error": {\n    "code": 403,\n    "message": "Cloud Machine Learning Engine has not been used in project 365008291484 before or it is disabled. Enable it by visiting https://console.developers.google.com/apis/api/ml.googleapis.com/overview?project=365008291484 then retry. If you enabled this API recently, wait a few minutes for the action to propagate to our systems and retry.",\n    "status": "PERMISSION_DENIED",\n    "details": [\n      {\n        "@type": "type.googleapis.com/google.rpc.Help",\n        "links": [\n          {\n            "description": "Google developers console API activation",\n            "url": "https://console.developers.google.com/apis/api/ml.googleapis.com/overview?project=365008291484"\n          }\n        ]\n      }\n    ]\n  }\n}\n'
2019-10-01 15:49:39,983 [INFO]  URL being requested: GET https://www.googleapis.com/discovery/v1/apis/ml/v1/rest
2019-10-01 15:49:40,330 [INFO]  URL being requested: POST https://ml.googleapis.com/v1/projects/ml-sandbox-1/models/Cash_Or_Credit:predict?alt=json
2019-10-01 15:49:40,538 [WARNI]  Invalid JSON content from response: b'{\n  "error": {\n    "code": 403,\n    "message": "Cloud Machine Learning Engine has not been used in project 365008291484 before or it is disabled. Enable it by visiting https://console.developers.google.com/apis/api/ml.googleapis.com/overview?project=365008291484 then retry. If you enabled this API recently, wait a few minutes for the action to propagate to our systems and retry.",\n    "status": "PERMISSION_DENIED",\n    "details": [\n      {\n        "@type": "type.googleapis.com/google.rpc.Help",\n        "links": [\n          {\n            "description": "Google developers console API activation",\n            "url": "https://console.developers.google.com/apis/api/ml.googleapis.com/overview?project=365008291484"\n          }\n        ]\n      }\n    ]\n  }\n}\n'
2019-10-01 15:50:57,656 [INFO]  URL being requested: GET https://www.googleapis.com/discovery/v1/apis/ml/v1/rest
2019-10-01 15:50:57,994 [INFO]  URL being requested: POST https://ml.googleapis.com/v1/projects/ml-sandbox-1-191918/models/Cash_Or_Credit:predict?alt=json
2019-10-01 15:53:07,377 [INFO]  URL being requested: GET https://www.googleapis.com/discovery/v1/apis/ml/v1/rest
2019-10-01 15:53:07,801 [INFO]  URL being requested: POST https://ml.googleapis.com/v1/projects/ml-sandbox-1-191918/models/taxi_model_1565105801:predict?alt=json
2019-10-01 15:56:13,749 [INFO]  URL being requested: GET https://www.googleapis.com/discovery/v1/apis/ml/v1/rest
2019-10-01 15:56:14,084 [INFO]  URL being requested: POST https://ml.googleapis.com/v1/projects/ml-sandbox-1-191918/models/taxi_model_1565105801:predict?alt=json
2019-10-01 15:56:18,035 [INFO]  URL being requested: GET https://www.googleapis.com/discovery/v1/apis/ml/v1/rest
2019-10-01 15:56:18,376 [INFO]  URL being requested: POST https://ml.googleapis.com/v1/projects/ml-sandbox-1-191918/models/taxi_model_1565105801:predict?alt=json
2019-10-01 15:56:35,231 [INFO]  URL being requested: GET https://www.googleapis.com/discovery/v1/apis/ml/v1/rest
2019-10-01 15:56:35,564 [INFO]  URL being requested: POST https://ml.googleapis.com/v1/projects/ml-sandbox-1-191918/models/taxi_model_1565105801:predict?alt=json
